[2023-09-06T05:10:29.686+0000] {taskinstance.py:1165} INFO - Dependencies all met for <TaskInstance: filtering_customer_consumption_backup.create_table manual__2023-09-06T05:10:22.539315+00:00 [queued]>
[2023-09-06T05:10:29.715+0000] {taskinstance.py:1165} INFO - Dependencies all met for <TaskInstance: filtering_customer_consumption_backup.create_table manual__2023-09-06T05:10:22.539315+00:00 [queued]>
[2023-09-06T05:10:29.716+0000] {taskinstance.py:1362} INFO - 
--------------------------------------------------------------------------------
[2023-09-06T05:10:29.717+0000] {taskinstance.py:1363} INFO - Starting attempt 1 of 1
[2023-09-06T05:10:29.718+0000] {taskinstance.py:1364} INFO - 
--------------------------------------------------------------------------------
[2023-09-06T05:10:29.754+0000] {taskinstance.py:1383} INFO - Executing <Task(PostgresOperator): create_table> on 2023-09-06 05:10:22.539315+00:00
[2023-09-06T05:10:29.767+0000] {standard_task_runner.py:55} INFO - Started process 347 to run task
[2023-09-06T05:10:29.771+0000] {standard_task_runner.py:82} INFO - Running: ['***', 'tasks', 'run', 'filtering_customer_consumption_backup', 'create_table', 'manual__2023-09-06T05:10:22.539315+00:00', '--job-id', '5', '--raw', '--subdir', 'DAGS_FOLDER/filtering_customer_consumption_backup.py', '--cfg-path', '/tmp/tmpe6o3aeq5']
[2023-09-06T05:10:29.775+0000] {standard_task_runner.py:83} INFO - Job 5: Subtask create_table
[2023-09-06T05:10:29.874+0000] {task_command.py:376} INFO - Running <TaskInstance: filtering_customer_consumption_backup.create_table manual__2023-09-06T05:10:22.539315+00:00 [running]> on host 60d3bee26398
[2023-09-06T05:10:30.010+0000] {taskinstance.py:1592} INFO - Exporting the following env vars:
AIRFLOW_CTX_DAG_OWNER=ductv50
AIRFLOW_CTX_DAG_ID=filtering_customer_consumption_backup
AIRFLOW_CTX_TASK_ID=create_table
AIRFLOW_CTX_EXECUTION_DATE=2023-09-06T05:10:22.539315+00:00
AIRFLOW_CTX_TRY_NUMBER=1
AIRFLOW_CTX_DAG_RUN_ID=manual__2023-09-06T05:10:22.539315+00:00
[2023-09-06T05:10:30.028+0000] {base.py:71} INFO - Using connection ID 'Postgress_1' for task execution.
[2023-09-06T05:10:30.035+0000] {taskinstance.py:1851} ERROR - Task failed with exception
Traceback (most recent call last):
  File "/home/airflow/.local/lib/python3.7/site-packages/airflow/providers/postgres/operators/postgres.py", line 94, in execute
    self.hook.run(self.sql, self.autocommit, parameters=self.parameters)
  File "/home/airflow/.local/lib/python3.7/site-packages/airflow/providers/common/sql/hooks/sql.py", line 288, in run
    with closing(self.get_conn()) as conn:
  File "/home/airflow/.local/lib/python3.7/site-packages/airflow/providers/postgres/hooks/postgres.py", line 115, in get_conn
    self.conn = psycopg2.connect(**conn_args)
  File "/home/airflow/.local/lib/python3.7/site-packages/psycopg2/__init__.py", line 122, in connect
    conn = _connect(dsn, connection_factory=connection_factory, **kwasync)
psycopg2.OperationalError: connection to server at "postgres" (172.18.0.3), port *** failed: FATAL:  password authentication failed for user "***"

[2023-09-06T05:10:30.057+0000] {taskinstance.py:1406} INFO - Marking task as FAILED. dag_id=filtering_customer_consumption_backup, task_id=create_table, execution_date=20230906T051022, start_date=20230906T051029, end_date=20230906T051030
[2023-09-06T05:10:30.081+0000] {standard_task_runner.py:105} ERROR - Failed to execute job 5 for task create_table (connection to server at "postgres" (172.18.0.3), port *** failed: FATAL:  password authentication failed for user "***"
; 347)
[2023-09-06T05:10:30.106+0000] {local_task_job.py:164} INFO - Task exited with return code 1
[2023-09-06T05:10:30.173+0000] {local_task_job.py:273} INFO - 0 downstream tasks scheduled from follow-on schedule check
