[2023-09-06T05:12:14.579+0000] {taskinstance.py:1165} INFO - Dependencies all met for <TaskInstance: filtering_customer_consumption_backup.create_table manual__2023-09-06T05:12:05.612425+00:00 [queued]>
[2023-09-06T05:12:14.623+0000] {taskinstance.py:1165} INFO - Dependencies all met for <TaskInstance: filtering_customer_consumption_backup.create_table manual__2023-09-06T05:12:05.612425+00:00 [queued]>
[2023-09-06T05:12:14.629+0000] {taskinstance.py:1362} INFO - 
--------------------------------------------------------------------------------
[2023-09-06T05:12:14.630+0000] {taskinstance.py:1363} INFO - Starting attempt 1 of 1
[2023-09-06T05:12:14.631+0000] {taskinstance.py:1364} INFO - 
--------------------------------------------------------------------------------
[2023-09-06T05:12:14.694+0000] {taskinstance.py:1383} INFO - Executing <Task(PostgresOperator): create_table> on 2023-09-06 05:12:05.612425+00:00
[2023-09-06T05:12:14.763+0000] {standard_task_runner.py:55} INFO - Started process 424 to run task
[2023-09-06T05:12:14.781+0000] {standard_task_runner.py:82} INFO - Running: ['***', 'tasks', 'run', 'filtering_customer_consumption_backup', 'create_table', 'manual__2023-09-06T05:12:05.612425+00:00', '--job-id', '7', '--raw', '--subdir', 'DAGS_FOLDER/filtering_customer_consumption_backup.py', '--cfg-path', '/tmp/tmpsjk67u9h']
[2023-09-06T05:12:14.807+0000] {standard_task_runner.py:83} INFO - Job 7: Subtask create_table
[2023-09-06T05:12:15.230+0000] {task_command.py:376} INFO - Running <TaskInstance: filtering_customer_consumption_backup.create_table manual__2023-09-06T05:12:05.612425+00:00 [running]> on host 60d3bee26398
[2023-09-06T05:12:15.751+0000] {taskinstance.py:1592} INFO - Exporting the following env vars:
AIRFLOW_CTX_DAG_OWNER=ductv50
AIRFLOW_CTX_DAG_ID=filtering_customer_consumption_backup
AIRFLOW_CTX_TASK_ID=create_table
AIRFLOW_CTX_EXECUTION_DATE=2023-09-06T05:12:05.612425+00:00
AIRFLOW_CTX_TRY_NUMBER=1
AIRFLOW_CTX_DAG_RUN_ID=manual__2023-09-06T05:12:05.612425+00:00
[2023-09-06T05:12:15.813+0000] {base.py:71} INFO - Using connection ID 'Postgress_1' for task execution.
[2023-09-06T05:12:15.832+0000] {sql.py:315} INFO - Running statement: 
        DROP TABLE consumption_alcoholic_20230906; 
        CREATE TABLE IF NOT EXISTS consumption_alcoholic_20230906 (
            category VARCHAR(255),
            sub_category VARCHAR(255),
            aggregation_date DATE,
            millions_of_dollar INT,            
            pipeline_exc_datetime TIMESTAMP
        );
    
        DROP TABLE consumption_cereals_bakery_20230906; 
        CREATE TABLE IF NOT EXISTS consumption_cereals_bakery_20230906 (
            category VARCHAR(255),
            sub_category VARCHAR(255),
            aggregation_date DATE,
            millions_of_dollar INT,            
            pipeline_exc_datetime TIMESTAMP
        );
    
        DROP TABLE consumption_meats_poultry_20230906; 
        CREATE TABLE IF NOT EXISTS consumption_meats_poultry_20230906 (
            category VARCHAR(255),
            sub_category VARCHAR(255),
            aggregation_date DATE,
            millions_of_dollar INT,            
            pipeline_exc_datetime TIMESTAMP
        );
    , parameters: None
[2023-09-06T05:12:15.910+0000] {taskinstance.py:1851} ERROR - Task failed with exception
Traceback (most recent call last):
  File "/home/airflow/.local/lib/python3.7/site-packages/airflow/providers/postgres/operators/postgres.py", line 94, in execute
    self.hook.run(self.sql, self.autocommit, parameters=self.parameters)
  File "/home/airflow/.local/lib/python3.7/site-packages/airflow/providers/common/sql/hooks/sql.py", line 295, in run
    self._run_command(cur, sql_statement, parameters)
  File "/home/airflow/.local/lib/python3.7/site-packages/airflow/providers/common/sql/hooks/sql.py", line 320, in _run_command
    cur.execute(sql_statement)
psycopg2.errors.UndefinedTable: table "consumption_alcoholic_20230906" does not exist

[2023-09-06T05:12:15.979+0000] {taskinstance.py:1406} INFO - Marking task as FAILED. dag_id=filtering_customer_consumption_backup, task_id=create_table, execution_date=20230906T051205, start_date=20230906T051214, end_date=20230906T051215
[2023-09-06T05:12:16.021+0000] {standard_task_runner.py:105} ERROR - Failed to execute job 7 for task create_table (table "consumption_alcoholic_20230906" does not exist
; 424)
[2023-09-06T05:12:16.078+0000] {local_task_job.py:164} INFO - Task exited with return code 1
[2023-09-06T05:12:16.188+0000] {local_task_job.py:273} INFO - 0 downstream tasks scheduled from follow-on schedule check
